Workbook

Sheet Master Grades
A1: Student | B1: ID | C1: SIS User ID | D1: SIS Login ID | E1: Section | F1: Student Id | G1: Interim Grade | H1: Grade | I1: Letter | J1: Homework 1 (464729) | K1: Homework 2 (464730) | L1: Homework 3 (464731) | M1: Homework 4 (464732) | N1: Assignment 1 (464747) | O1: Assignment 2 (464748) | P1: Assignment 3 (464749) | Q1: Presentation (464745)
A2: Points Possible | F2: (read only) | G2: =J2+K2+L2+M2+N2+O2+P2+Q2 -> 100 | J2: ='Homework 1'!C2 -> 5 | K2: ='Homework 2'!C2 -> 5 | L2: ='Homework 3'!C2 -> 5 | M2: ='Homework 4'!C2 -> 5 | N2: ='Assignment 1'!C2 -> 20 | O2: ='Assignment 2'!C2 -> 20 | P2: ='Assignment 3'!C2 -> 20 | Q2: =Presentation!C2 -> 20
A3: CAO, Zhi | B3: 279200 | C3: 1370675 | D3: zhcao2 | E3: Computational Differential Equations (MAST90026_2024_SM1), Practical 1 (1), and Practical 2 (1) | F3: 1370675 | G3: =J3+K3+L3+M3+N3+O3+P3+Q3 -> 74.25 | H3: =_xlfn.CEILING.MATH((G3)) -> 75 | I3: =IF(H3>=80,"H1",IF(H3>=75,"H2A",IF(H3>=70,"H2B",IF(H3>=65,"H3",IF(H3>=50,"P","N"))))) -> H2A | J3: ='Homework 1'!C3 -> 4 | K3: ='Homework 2'!C3 -> 1.75 | L3: ='Homework 3'!C3 -> 4.25 | M3: ='Homework 4'!C3 -> 4 | N3: ='Assignment 1'!C3 -> 17.5 | O3: ='Assignment 2'!C3 -> 11.5 | P3: ='Assignment 3'!C3 -> 15 | Q3: =Presentation!C3 -> 16.25 | S3: H1 | T3: =COUNTIF(I3:I42,"H1") -> 20
A4: Cash, Lachlan | B4: 46291 | C4: 995802 | D4: lcash | E4: Computational Differential Equations (MAST90026_2024_SM1), Practical 1 (1), and Practical 2 (1) | F4: 995802 | G4: =J4+K4+L4+M4+N4+O4+P4+Q4 -> 93 | H4: =_xlfn.CEILING.MATH((G4)) -> 93 | I4: =IF(H4>=80,"H1",IF(H4>=75,"H2A",IF(H4>=70,"H2B",IF(H4>=65,"H3",IF(H4>=50,"P","N"))))) -> H1 | J4: ='Homework 1'!C4 -> 4.75 | K4: ='Homework 2'!C4 -> 5 | L4: ='Homework 3'!C4 -> 4.75 | M4: ='Homework 4'!C4 -> 4 | N4: ='Assignment 1'!C4 -> 19.5 | O4: ='Assignment 2'!C4 -> 16.5 | P4: ='Assignment 3'!C4 -> 19 | Q4: =Presentation!C4 -> 19.5 | S4: H2A | T4: =COUNTIF(I3:I42,"H2A") -> 7
A5: CHEN, Yiru | B5: 287672 | C5: 1417057 | D5: yiruchen3 | E5: Computational Differential Equations (MAST90026_2024_SM1), Practical 1 (1), and Practical 2 (1) | F5: 1417057 | G5: =J5+K5+L5+M5+N5+O5+P5+Q5 -> 96.5 | H5: =_xlfn.CEILING.MATH((G5)) -> 97 | I5: =IF(H5>=80,"H1",IF(H5>=75,"H2A",IF(H5>=70,"H2B",IF(H5>=65,"H3",IF(H5>=50,"P","N"))))) -> H1 | J5: ='Homework 1'!C5 -> 5 | K5: ='Homework 2'!C5 -> 5 | L5: ='Homework 3'!C5 -> 4.75 | M5: ='Homework 4'!C5 -> 5 | N5: ='Assignment 1'!C5 -> 19.5 | O5: ='Assignment 2'!C5 -> 19.5 | P5: ='Assignment 3'!C5 -> 19.5 | Q5: =Presentation!C5 -> 18.25 | S5: H2B | T5: =COUNTIF(I3:I42,"H2B") -> 6
A6: Chen, Yuning | B6: 270353 | C6: 1374388 | D6: yunichen1 | E6: Computational Differential Equations (MAST90026_2024_SM1), Practical 1 (1), and Practical 2 (1) | F6: 1374388 | G6: =J6+K6+L6+M6+N6+O6+P6+Q6 -> 74.5 | H6: =_xlfn.CEILING.MATH((G6)) -> 75 | I6: =IF(H6>=80,"H1",IF(H6>=75,"H2A",IF(H6>=70,"H2B",IF(H6>=65,"H3",IF(H6>=50,"P","N"))))) -> H2A | J6: ='Homework 1'!C6 -> 4.5 | K6: ='Homework 2'!C6 -> 5 | L6: ='Homework 3'!C6 -> 4.75 | M6: ='Homework 4'!C6 -> 3.5 | N6: ='Assignment 1'!C6 -> 13 | O6: ='Assignment 2'!C6 -> 12.5 | P6: ='Assignment 3'!C6 -> 15 | Q6: =Presentation!C6 -> 16.25 | S6: H3 | T6: =COUNTIF(I3:I42,"H3") -> 2
A7: CUI, Kaiyue | B7: 299695 | C7: 1373562 | D7: kccu1 | E7: Computational Differential Equations (MAST90026_2024_SM1), Practical 1 (1), and Practical 2 (1) | F7: 1373562 | G7: =J7+K7+L7+M7+N7+O7+P7+Q7 -> 94.75 | H7: =_xlfn.CEILING.MATH((G7)) -> 95 | I7: =IF(H7>=80,"H1",IF(H7>=75,"H2A",IF(H7>=70,"H2B",IF(H7>=65,"H3",IF(H7>=50,"P","N"))))) -> H1 | J7: ='Homework 1'!C7 -> 5 | K7: ='Homework 2'!C7 -> 5 | L7: ='Homework 3'!C7 -> 4.75 | M7: ='Homework 4'!C7 -> 5 | N7: ='Assignment 1'!C7 -> 19.5 | O7: ='Assignment 2'!C7 -> 18 | P7: ='Assignment 3'!C7 -> 19.5 | Q7: =Presentation!C7 -> 18 | S7: P | T7: =COUNTIF(I3:I42,"P") -> 2
A8: Douglas, Gabe | B8: 288207 | C8: 1443406 | D8: gvdouglas | E8: Computational Differential Equations (MAST90026_2024_SM1), Practical 1 (1), and Practical 2 (1) | F8: 1443406 | G8: =J8+K8+L8+M8+N8+O8+P8+Q8 -> 90 | H8: =_xlfn.CEILING.MATH((G8)) -> 90 | I8: =IF(H8>=80,"H1",IF(H8>=75,"H2A",IF(H8>=70,"H2B",IF(H8>=65,"H3",IF(H8>=50,"P","N"))))) -> H1 | J8: ='Homework 1'!C8 -> 4.75 | K8: ='Homework 2'!C8 -> 5 | L8: ='Homework 3'!C8 -> 5 | M8: ='Homework 4'!C8 -> 5 | N8: ='Assignment 1'!C8 -> 17 | O8: ='Assignment 2'!C8 -> 16 | P8: ='Assignment 3'!C8 -> 18 | Q8: =Presentation!C8 -> 19.25 | S8: N | T8: =COUNTIF(I3:I42,"N") -> 1
A9: Effiezal Aswadi, Afiq | B9: 356171 | C9: 1555968 | D9: aeffiezalasw | E9: Computational Differential Equations (MAST90026_2024_SM1), Practical 1 (1), and Practical 2 (1) | F9: 1555968 | G9: =J9+K9+L9+M9+N9+O9+P9+Q9 -> 87.25 | H9: =_xlfn.CEILING.MATH((G9)) -> 88 | I9: =IF(H9>=80,"H1",IF(H9>=75,"H2A",IF(H9>=70,"H2B",IF(H9>=65,"H3",IF(H9>=50,"P","N"))))) -> H1 | J9: ='Homework 1'!C9 -> 4.75 | K9: ='Homework 2'!C9 -> 4.25 | L9: ='Homework 3'!C9 -> 2.5 | M9: ='Homework 4'!C9 -> 4 | N9: ='Assignment 1'!C9 -> 18.5 | O9: ='Assignment 2'!C9 -> 19 | P9: ='Assignment 3'!C9 -> 17 | Q9: =Presentation!C9 -> 17.25 | S9: Total | T9: =SUM(T3:T8) -> 38
A10: GONG, Lishi | B10: 324402 | C10: 1436599 | D10: lisgong | E10: Computational Differential Equations (MAST90026_2024_SM1), Practical 1 (1), and Practical 2 (1) | F10: 1436599 | G10: =J10+K10+L10+M10+N10+O10+P10+Q10 -> 69.75 | H10: =_xlfn.CEILING.MATH((G10)) -> 70 | I10: =IF(H10>=80,"H1",IF(H10>=75,"H2A",IF(H10>=70,"H2B",IF(H10>=65,"H3",IF(H10>=50,"P","N"))))) -> H2B | J10: ='Homework 1'!C10 -> 4.5 | K10: ='Homework 2'!C10 -> 4.5 | L10: ='Homework 3'!C10 -> 3 | M10: ='Homework 4'!C10 -> 4 | N10: ='Assignment 1'!C10 -> 8.5 | O10: ='Assignment 2'!C10 -> 12.75 | P10: ='Assignment 3'!C10 -> 17 | Q10: =Presentation!C10 -> 15.5
A11: Griffin, Joel | B11: 17737 | C11: 1072476 | D11: jggrif | E11: Computational Differential Equations (MAST90026_2024_SM1), Practical 1 (1), and Practical 2 (1) | F11: 1072476 | G11: =J11+K11+L11+M11+N11+O11+P11+Q11 -> 94.75 | H11: =_xlfn.CEILING.MATH((G11)) -> 95 | I11: =IF(H11>=80,"H1",IF(H11>=75,"H2A",IF(H11>=70,"H2B",IF(H11>=65,"H3",IF(H11>=50,"P","N"))))) -> H1 | J11: ='Homework 1'!C11 -> 5 | K11: ='Homework 2'!C11 -> 5 | L11: ='Homework 3'!C11 -> 5 | M11: ='Homework 4'!C11 -> 5 | N11: ='Assignment 1'!C11 -> 17 | O11: ='Assignment 2'!C11 -> 20 | P11: ='Assignment 3'!C11 -> 19.5 | Q11: =Presentation!C11 -> 18.25
A12: HUANG, Yiran | B12: 299114 | C12: 1316006 | D12: yiranhuang | E12: Computational Differential Equations (MAST90026_2024_SM1), Practical 1 (1), and Practical 2 (1) | F12: 1316006 | G12: =J12+K12+L12+M12+N12+O12+P12+Q12 -> 79 | H12: =_xlfn.CEILING.MATH((G12)) -> 79 | I12: =IF(H12>=80,"H1",IF(H12>=75,"H2A",IF(H12>=70,"H2B",IF(H12>=65,"H3",IF(H12>=50,"P","N"))))) -> H2A | J12: ='Homework 1'!C12 -> 4.5 | K12: ='Homework 2'!C12 -> 2.75 | L12: ='Homework 3'!C12 -> 4.5 | M12: ='Homework 4'!C12 -> 4.5 | N12: ='Assignment 1'!C12 -> 15 | O12: ='Assignment 2'!C12 -> 17 | P12: ='Assignment 3'!C12 -> 16 | Q12: =Presentation!C12 -> 14.75
A13: Iqbal, Shadman | B13: 18670 | C13: 650596 | D13: shadmani | E13: Computational Differential Equations (MAST90026_2024_SM1), Practical 1 (1), and Practical 2 (1) | F13: 650596 | G13: =J13+K13+L13+M13+N13+O13+P13+Q13 -> 60 | H13: =_xlfn.CEILING.MATH((G13)) -> 60 | I13: =IF(H13>=80,"H1",IF(H13>=75,"H2A",IF(H13>=70,"H2B",IF(H13>=65,"H3",IF(H13>=50,"P","N"))))) -> P | J13: ='Homework 1'!C13 -> 1.25 | K13: ='Homework 2'!C13 -> 5 | L13: ='Homework 3'!C13 -> 4.25 | M13: ='Homework 4'!C13 -> 4 | N13: ='Assignment 1'!C13 -> 16 | O13: ='Assignment 2'!C13 -> 13 | P13: ='Assignment 3'!C13 -> 0 | Q13: =Presentation!C13 -> 16.5
A14: Jayanthy, Danielle | B14: 17815 | C14: 1063490 | D14: ssarwesvaran | E14: Computational Differential Equations (MAST90026_2024_SM1), Practical 1 (1), and Practical 2 (1) | F14: 1063490 | G14: =J14+K14+L14+M14+N14+O14+P14+Q14 -> 68.25 | H14: =_xlfn.CEILING.MATH((G14)) -> 69 | I14: =IF(H14>=80,"H1",IF(H14>=75,"H2A",IF(H14>=70,"H2B",IF(H14>=65,"H3",IF(H14>=50,"P","N"))))) -> H3 | J14: ='Homework 1'!C14 -> 2.5 | K14: ='Homework 2'!C14 -> 3.75 | L14: ='Homework 3'!C14 -> 2.5 | M14: ='Homework 4'!C14 -> 3.75 | N14: ='Assignment 1'!C14 -> 14.5 | O14: ='Assignment 2'!C14 -> 11.5 | P14: ='Assignment 3'!C14 -> 11 | Q14: =Presentation!C14 -> 18.75
A15: Jiang, Zhuochen | B15: 323995 | C15: 1502683 | D15: zhuochenj | E15: Computational Differential Equations (MAST90026_2024_SM1), Practical 1 (1), and Practical 2 (1) | F15: 1502683 | G15: =J15+K15+L15+M15+N15+O15+P15+Q15 -> 71.5 | H15: =_xlfn.CEILING.MATH((G15)) -> 72 | I15: =IF(H15>=80,"H1",IF(H15>=75,"H2A",IF(H15>=70,"H2B",IF(H15>=65,"H3",IF(H15>=50,"P","N"))))) -> H2B | J15: ='Homework 1'!C15 -> 4.25 | K15: ='Homework 2'!C15 -> 3.5 | L15: ='Homework 3'!C15 -> 4 | M15: ='Homework 4'!C15 -> 3.5 | N15: ='Assignment 1'!C15 -> 11.5 | O15: ='Assignment 2'!C15 -> 14 | P15: ='Assignment 3'!C15 -> 14.5 | Q15: =Presentation!C15 -> 16.25
A16: Kim, Jiseon | B16: 37642 | C16: 884343 | D16: jiseonk | E16: Computational Differential Equations (MAST90026_2024_SM1), Practical 1 (1), and Practical 2 (1) | F16: 884343 | G16: =J16+K16+L16+M16+N16+O16+P16+Q16 -> 84 | H16: =_xlfn.CEILING.MATH((G16)) -> 84 | I16: =IF(H16>=80,"H1",IF(H16>=75,"H2A",IF(H16>=70,"H2B",IF(H16>=65,"H3",IF(H16>=50,"P","N"))))) -> H1 | J16: ='Homework 1'!C16 -> 5 | K16: ='Homework 2'!C16 -> 4 | L16: ='Homework 3'!C16 -> 2.25 | M16: ='Homework 4'!C16 -> 4 | N16: ='Assignment 1'!C16 -> 14 | O16: ='Assignment 2'!C16 -> 17.25 | P16: ='Assignment 3'!C16 -> 19.5 | Q16: =Presentation!C16 -> 18
A17: Li, Juji | B17: 329858 | C17: 1510683 | D17: jujil | E17: Computational Differential Equations (MAST90026_2024_SM1), Practical 1 (1), and Practical 2 (1) | F17: 1510683 | G17: =J17+K17+L17+M17+N17+O17+P17+Q17 -> 73.5 | H17: =_xlfn.CEILING.MATH((G17)) -> 74 | I17: =IF(H17>=80,"H1",IF(H17>=75,"H2A",IF(H17>=70,"H2B",IF(H17>=65,"H3",IF(H17>=50,"P","N"))))) -> H2B | J17: ='Homework 1'!C17 -> 4.5 | K17: ='Homework 2'!C17 -> 3.25 | L17: ='Homework 3'!C17 -> 2.75 | M17: ='Homework 4'!C17 -> 4 | N17: ='Assignment 1'!C17 -> 12 | O17: ='Assignment 2'!C17 -> 15.75 | P17: ='Assignment 3'!C17 -> 15.5 | Q17: =Presentation!C17 -> 15.75
A18: Li, Zhihan | B18: 71451 | C18: 1074491 | D18: zhihan2 | E18: Computational Differential Equations (MAST90026_2024_SM1), Practical 1 (1), and Practical 2 (1) | F18: 1074491 | G18: =J18+K18+L18+M18+N18+O18+P18+Q18 -> 72.75 | H18: =_xlfn.CEILING.MATH((G18)) -> 73 | I18: =IF(H18>=80,"H1",IF(H18>=75,"H2A",IF(H18>=70,"H2B",IF(H18>=65,"H3",IF(H18>=50,"P","N"))))) -> H2B | J18: ='Homework 1'!C18 -> 1.75 | K18: ='Homework 2'!C18 -> 2 | L18: ='Homework 3'!C18 -> 4.75 | M18: ='Homework 4'!C18 -> 4.25 | N18: ='Assignment 1'!C18 -> 15.5 | O18: ='Assignment 2'!C18 -> 13.5 | P18: ='Assignment 3'!C18 -> 17 | Q18: =Presentation!C18 -> 14
A19: Ma, Jiayue | B19: 317752 | C19: 1495622 | D19: jiayuem2 | E19: Computational Differential Equations (MAST90026_2024_SM1), Practical 1 (1), and Practical 2 (1) | F19: 1495622 | G19: =J19+K19+L19+M19+N19+O19+P19+Q19 -> 68 | H19: =_xlfn.CEILING.MATH((G19)) -> 68 | I19: =IF(H19>=80,"H1",IF(H19>=75,"H2A",IF(H19>=70,"H2B",IF(H19>=65,"H3",IF(H19>=50,"P","N"))))) -> H3 | J19: ='Homework 1'!C19 -> 2.5 | K19: ='Homework 2'!C19 -> 1.75 | L19: ='Homework 3'!C19 -> 2.25 | M19: ='Homework 4'!C19 -> 4.5 | N19: ='Assignment 1'!C19 -> 12.5 | O19: ='Assignment 2'!C19 -> 12.75 | P19: ='Assignment 3'!C19 -> 16 | Q19: =Presentation!C19 -> 15.75
A20: Mccallum, Liam | B20: 41156 | C20: 992893 | D20: lmccallum | E20: Computational Differential Equations (MAST90026_2024_SM1), Practical 1 (1), and Practical 2 (1) | F20: 992893 | G20: =J20+K20+L20+M20+N20+O20+P20+Q20 -> 83.25 | H20: =_xlfn.CEILING.MATH((G20)) -> 84 | I20: =IF(H20>=80,"H1",IF(H20>=75,"H2A",IF(H20>=70,"H2B",IF(H20>=65,"H3",IF(H20>=50,"P","N"))))) -> H1 | J20: ='Homework 1'!C20 -> 4.75 | K20: ='Homework 2'!C20 -> 4.5 | L20: ='Homework 3'!C20 -> 4.75 | M20: ='Homework 4'!C20 -> 4 | N20: ='Assignment 1'!C20 -> 17.5 | O20: ='Assignment 2'!C20 -> 14.25 | P20: ='Assignment 3'!C20 -> 15.5 | Q20: =Presentation!C20 -> 18
A21: Mifsud, Nathanael | B21: 129673 | C21: 1181978 | D21: ntmifsud | E21: Computational Differential Equations (MAST90026_2024_SM1), Practical 1 (1), and Practical 2 (1) | F21: 1181978 | G21: =J21+K21+L21+M21+N21+O21+P21+Q21 -> 89.75 | H21: =_xlfn.CEILING.MATH((G21)) -> 90 | I21: =IF(H21>=80,"H1",IF(H21>=75,"H2A",IF(H21>=70,"H2B",IF(H21>=65,"H3",IF(H21>=50,"P","N"))))) -> H1 | J21: ='Homework 1'!C21 -> 4.5 | K21: ='Homework 2'!C21 -> 5 | L21: ='Homework 3'!C21 -> 4.25 | M21: ='Homework 4'!C21 -> 4.5 | N21: ='Assignment 1'!C21 -> 16 | O21: ='Assignment 2'!C21 -> 19 | P21: ='Assignment 3'!C21 -> 17 | Q21: =Presentation!C21 -> 19.5
A22: Ouyang, Yorking | B22: 61271 | C22: 1051214 | D22: youjiano | E22: Computational Differential Equations (MAST90026_2024_SM1), Practical 1 (1), and Practical 2 (1) | F22: 1051214 | G22: =J22+K22+L22+M22+N22+O22+P22+Q22 -> 90.5 | H22: =_xlfn.CEILING.MATH((G22)) -> 91 | I22: =IF(H22>=80,"H1",IF(H22>=75,"H2A",IF(H22>=70,"H2B",IF(H22>=65,"H3",IF(H22>=50,"P","N"))))) -> H1 | J22: ='Homework 1'!C22 -> 5 | K22: ='Homework 2'!C22 -> 5 | L22: ='Homework 3'!C22 -> 4.75 | M22: ='Homework 4'!C22 -> 5 | N22: ='Assignment 1'!C22 -> 17.5 | O22: ='Assignment 2'!C22 -> 18.75 | P22: ='Assignment 3'!C22 -> 19.5 | Q22: =Presentation!C22 -> 15
A23: Rammohan, Radhik | B23: 325621 | C23: ex.rrammohan | D23: ex.rrammohan | E23: MAST90026_2024_SM1 (External Users) | G23: =J23+K23+L23+M23+N23+O23+P23+Q23 -> 0 | J23: ='Homework 1'!C23 -> 0 | K23: ='Homework 2'!C23 -> 0 | L23: ='Homework 3'!C23 -> 0 | M23: ='Homework 4'!C23 -> 0 | N23: ='Assignment 1'!C23 -> 0 | O23: ='Assignment 2'!C23 -> 0 | P23: ='Assignment 3'!C23 -> 0 | Q23: =Presentation!C23 -> 0
A24: Sheng, Kwan | B24: 360747 | C24: ex.shengk | D24: ex.shengk | E24: MAST90026_2024_SM1 (External Users) | G24: =J24+K24+L24+M24+N24+O24+P24+Q24 -> 0 | J24: ='Homework 1'!C24 -> 0 | K24: ='Homework 2'!C24 -> 0 | L24: ='Homework 3'!C24 -> 0 | M24: ='Homework 4'!C24 -> 0 | N24: ='Assignment 1'!C24 -> 0 | O24: ='Assignment 2'!C24 -> 0 | P24: ='Assignment 3'!C24 -> 0 | Q24: =Presentation!C24 -> 0
A25: Smith, Zac | B25: 341688 | C25: 1549443 | D25: zacs | E25: Computational Differential Equations (MAST90026_2024_SM1), Practical 1 (1), and Practical 2 (1) | F25: 1549443 | G25: =J25+K25+L25+M25+N25+O25+P25+Q25 -> 74 | H25: =_xlfn.CEILING.MATH((G25)) -> 74 | I25: =IF(H25>=80,"H1",IF(H25>=75,"H2A",IF(H25>=70,"H2B",IF(H25>=65,"H3",IF(H25>=50,"P","N"))))) -> H2B | J25: ='Homework 1'!C25 -> 4.5 | K25: ='Homework 2'!C25 -> 3.5 | L25: ='Homework 3'!C25 -> 3.5 | M25: ='Homework 4'!C25 -> 3 | N25: ='Assignment 1'!C25 -> 12 | O25: ='Assignment 2'!C25 -> 13 | P25: ='Assignment 3'!C25 -> 15.5 | Q25: =Presentation!C25 -> 19
A26: SUN, Guangyue | B26: 324192 | C26: 1510033 | D26: guangyue | E26: Computational Differential Equations (MAST90026_2024_SM1), Practical 1 (1), and Practical 2 (1) | F26: 1510033 | G26: =J26+K26+L26+M26+N26+O26+P26+Q26 -> 42 | H26: =_xlfn.CEILING.MATH((G26)) -> 42 | I26: =IF(H26>=80,"H1",IF(H26>=75,"H2A",IF(H26>=70,"H2B",IF(H26>=65,"H3",IF(H26>=50,"P","N"))))) -> N | J26: ='Homework 1'!C26 -> 3.25 | K26: ='Homework 2'!C26 -> 3.5 | L26: ='Homework 3'!C26 -> 1.75 | M26: ='Homework 4'!C26 -> 0.75 | N26: =('Assignment 1'!C26 + 4.5)/2 -> 5.5 | O26: =('Assignment 2'!C26 + 3)/2 -> 4.75 | P26: =('Assignment 3'!C26 + 11)/2 -> 9 | Q26: =Presentation!C26 -> 13.5
A27: Sutherland, William | B27: 120224 | C27: 1168383 | D27: wfsutherland | E27: Computational Differential Equations (MAST90026_2024_SM1), Practical 1 (1), and Practical 2 (1) | F27: 1168383 | G27: =J27+K27+L27+M27+N27+O27+P27+Q27 -> 76.5 | H27: =_xlfn.CEILING.MATH((G27)) -> 77 | I27: =IF(H27>=80,"H1",IF(H27>=75,"H2A",IF(H27>=70,"H2B",IF(H27>=65,"H3",IF(H27>=50,"P","N"))))) -> H2A | J27: ='Homework 1'!C27 -> 2.75 | K27: ='Homework 2'!C27 -> 1.5 | L27: ='Homework 3'!C27 -> 3.25 | M27: ='Homework 4'!C27 -> 4.5 | N27: ='Assignment 1'!C27 -> 9 | O27: ='Assignment 2'!C27 -> 17.25 | P27: ='Assignment 3'!C27 -> 19 | Q27: =Presentation!C27 -> 19.25
A28: Syed Muhammad Naquib Al Aidrus, Nadia | B28: 319407 | C28: 1436936 | D28: sharifahnadi | E28: Computational Differential Equations (MAST90026_2024_SM1), Practical 1 (1), and Practical 2 (1) | F28: 1436936 | G28: =J28+K28+L28+M28+N28+O28+P28+Q28 -> 73 | H28: =_xlfn.CEILING.MATH((G28)) -> 73 | I28: =IF(H28>=80,"H1",IF(H28>=75,"H2A",IF(H28>=70,"H2B",IF(H28>=65,"H3",IF(H28>=50,"P","N"))))) -> H2B | J28: ='Homework 1'!C28 -> 4.5 | K28: ='Homework 2'!C28 -> 2.75 | L28: ='Homework 3'!C28 -> 3.25 | M28: ='Homework 4'!C28 -> 4.25 | N28: ='Assignment 1'!C28 -> 10.5 | O28: ='Assignment 2'!C28 -> 15 | P28: ='Assignment 3'!C28 -> 14.5 | Q28: =Presentation!C28 -> 18.25
A29: Tian, Lutong | B29: 270656 | C29: 1322753 | D29: lutongt | E29: Computational Differential Equations (MAST90026_2024_SM1), Practical 1 (1), and Practical 2 (1) | F29: 1322753 | G29: =J29+K29+L29+M29+N29+O29+P29+Q29 -> 76.25 | H29: =_xlfn.CEILING.MATH((G29)) -> 77 | I29: =IF(H29>=80,"H1",IF(H29>=75,"H2A",IF(H29>=70,"H2B",IF(H29>=65,"H3",IF(H29>=50,"P","N"))))) -> H2A | J29: ='Homework 1'!C29 -> 3.75 | K29: ='Homework 2'!C29 -> 4 | L29: ='Homework 3'!C29 -> 4 | M29: ='Homework 4'!C29 -> 4 | N29: ='Assignment 1'!C29 -> 14.5 | O29: ='Assignment 2'!C29 -> 14.75 | P29: ='Assignment 3'!C29 -> 16.5 | Q29: =Presentation!C29 -> 14.75
A30: Todd, Matthew | B30: 298126 | C30: 1474916 | D30: mstodd | E30: Computational Differential Equations (MAST90026_2024_SM1), Practical 1 (1), and Practical 2 (1) | F30: 1474916 | G30: =J30+K30+L30+M30+N30+O30+P30+Q30 -> 84 | H30: =_xlfn.CEILING.MATH((G30)) -> 84 | I30: =IF(H30>=80,"H1",IF(H30>=75,"H2A",IF(H30>=70,"H2B",IF(H30>=65,"H3",IF(H30>=50,"P","N"))))) -> H1 | J30: ='Homework 1'!C30 -> 4.5 | K30: ='Homework 2'!C30 -> 4 | L30: ='Homework 3'!C30 -> 4.25 | M30: ='Homework 4'!C30 -> 4.75 | N30: ='Assignment 1'!C30 -> 16.5 | O30: ='Assignment 2'!C30 -> 16.5 | P30: ='Assignment 3'!C30 -> 14.75 | Q30: =Presentation!C30 -> 18.75
A31: Wei, Yizhou | B31: 266643 | C31: 1036484 | D31: yizwei | E31: Computational Differential Equations (MAST90026_2024_SM1), Practical 1 (1), and Practical 2 (1) | F31: 1036484 | G31: =J31+K31+L31+M31+N31+O31+P31+Q31 -> 95 | H31: =_xlfn.CEILING.MATH((G31)) -> 95 | I31: =IF(H31>=80,"H1",IF(H31>=75,"H2A",IF(H31>=70,"H2B",IF(H31>=65,"H3",IF(H31>=50,"P","N"))))) -> H1 | J31: ='Homework 1'!C31 -> 5 | K31: ='Homework 2'!C31 -> 5 | L31: ='Homework 3'!C31 -> 4.75 | M31: ='Homework 4'!C31 -> 5 | N31: ='Assignment 1'!C31 -> 19.5 | O31: ='Assignment 2'!C31 -> 19.5 | P31: ='Assignment 3'!C31 -> 19 | Q31: =Presentation!C31 -> 17.25
A32: Wu, Yilei | B32: 295645 | C32: 1349379 | D32: yilei2 | E32: Computational Differential Equations (MAST90026_2024_SM1), Practical 1 (1), and Practical 2 (1) | F32: 1349379 | G32: =J32+K32+L32+M32+N32+O32+P32+Q32 -> 79 | H32: =_xlfn.CEILING.MATH((G32)) -> 79 | I32: =IF(H32>=80,"H1",IF(H32>=75,"H2A",IF(H32>=70,"H2B",IF(H32>=65,"H3",IF(H32>=50,"P","N"))))) -> H2A | J32: ='Homework 1'!C32 -> 2.5 | K32: ='Homework 2'!C32 -> 5 | L32: ='Homework 3'!C32 -> 2.75 | M32: ='Homework 4'!C32 -> 5 | N32: ='Assignment 1'!C32 -> 14.5 | O32: ='Assignment 2'!C32 -> 16.5 | P32: ='Assignment 3'!C32 -> 16.5 | Q32: =Presentation!C32 -> 16.25
A33: Xiao, Shutian | B33: 316307 | C33: 1464811 | D33: shutxiao | E33: Computational Differential Equations (MAST90026_2024_SM1), Practical 1 (1), and Practical 2 (1) | F33: 1464811 | G33: =J33+K33+L33+M33+N33+O33+P33+Q33 -> 94 | H33: =_xlfn.CEILING.MATH((G33)) -> 94 | I33: =IF(H33>=80,"H1",IF(H33>=75,"H2A",IF(H33>=70,"H2B",IF(H33>=65,"H3",IF(H33>=50,"P","N"))))) -> H1 | J33: ='Homework 1'!C33 -> 5 | K33: ='Homework 2'!C33 -> 5 | L33: ='Homework 3'!C33 -> 4.75 | M33: ='Homework 4'!C33 -> 5 | N33: ='Assignment 1'!C33 -> 18.5 | O33: ='Assignment 2'!C33 -> 19.5 | P33: ='Assignment 3'!C33 -> 18.5 | Q33: =Presentation!C33 -> 17.75
A34: YAN, Kun | B34: 355694 | C34: 1177465 | D34: kunyan | E34: Computational Differential Equations (MAST90026_2024_SM1), Practical 1 (1), and Practical 2 (1) | F34: 1177465 | G34: =J34+K34+L34+M34+N34+O34+P34+Q34 -> 84.75 | H34: =_xlfn.CEILING.MATH((G34)) -> 85 | I34: =IF(H34>=80,"H1",IF(H34>=75,"H2A",IF(H34>=70,"H2B",IF(H34>=65,"H3",IF(H34>=50,"P","N"))))) -> H1 | J34: ='Homework 1'!C34 -> 4.75 | K34: ='Homework 2'!C34 -> 5 | L34: ='Homework 3'!C34 -> 4.25 | M34: ='Homework 4'!C34 -> 5 | N34: ='Assignment 1'!C34 -> 15.5 | O34: ='Assignment 2'!C34 -> 16 | P34: ='Assignment 3'!C34 -> 16.5 | Q34: =Presentation!C34 -> 17.75
A35: Young, Carson | B35: 17220 | C35: 1086178 | D35: kashuncarson | E35: Computational Differential Equations (MAST90026_2024_SM1), Practical 1 (1), and Practical 2 (1) | F35: 1086178 | G35: =J35+K35+L35+M35+N35+O35+P35+Q35 -> 94.25 | H35: =_xlfn.CEILING.MATH((G35)) -> 95 | I35: =IF(H35>=80,"H1",IF(H35>=75,"H2A",IF(H35>=70,"H2B",IF(H35>=65,"H3",IF(H35>=50,"P","N"))))) -> H1 | J35: ='Homework 1'!C35 -> 5 | K35: ='Homework 2'!C35 -> 5 | L35: ='Homework 3'!C35 -> 5 | M35: ='Homework 4'!C35 -> 5 | N35: ='Assignment 1'!C35 -> 16.5 | O35: ='Assignment 2'!C35 -> 20 | P35: ='Assignment 3'!C35 -> 19 | Q35: =Presentation!C35 -> 18.75
A36: Yuan, Zuoting | B36: 350360 | C36: 1533296 | D36: zuotingy | E36: Computational Differential Equations (MAST90026_2024_SM1), Practical 1 (1), and Practical 2 (1) | F36: 1533296 | G36: =J36+K36+L36+M36+N36+O36+P36+Q36 -> 50 | H36: =_xlfn.CEILING.MATH((G36)) -> 50 | I36: =IF(H36>=80,"H1",IF(H36>=75,"H2A",IF(H36>=70,"H2B",IF(H36>=65,"H3",IF(H36>=50,"P","N"))))) -> P | J36: ='Homework 1'!C36 -> 2.5 | K36: ='Homework 2'!C36 -> 1.5 | L36: ='Homework 3'!C36 -> 1 | M36: ='Homework 4'!C36 -> 4 | N36: ='Assignment 1'!C36 -> 9.5 | O36: ='Assignment 2'!C36 -> 8.75 | P36: ='Assignment 3'!C36 -> 9 | Q36: =Presentation!C36 -> 13.75
A37: Zhang, Andrew | B37: 36628 | C37: 979356 | D37: azzhan | E37: Computational Differential Equations (MAST90026_2024_SM1), Practical 1 (1), and Practical 2 (1) | F37: 979356 | G37: =J37+K37+L37+M37+N37+O37+P37+Q37 -> 91 | H37: =_xlfn.CEILING.MATH((G37)) -> 91 | I37: =IF(H37>=80,"H1",IF(H37>=75,"H2A",IF(H37>=70,"H2B",IF(H37>=65,"H3",IF(H37>=50,"P","N"))))) -> H1 | J37: ='Homework 1'!C37 -> 5 | K37: ='Homework 2'!C37 -> 5 | L37: ='Homework 3'!C37 -> 5 | M37: ='Homework 4'!C37 -> 5 | N37: ='Assignment 1'!C37 -> 14.5 | O37: ='Assignment 2'!C37 -> 20 | P37: ='Assignment 3'!C37 -> 19.25 | Q37: =Presentation!C37 -> 17.25
A38: ZHANG, Ziang | B38: 330140 | C38: 1494354 | D38: zianzhang1 | E38: Computational Differential Equations (MAST90026_2024_SM1), Practical 1 (1), and Practical 2 (1) | F38: 1494354 | G38: =J38+K38+L38+M38+N38+O38+P38+Q38 -> 86 | H38: =_xlfn.CEILING.MATH((G38)) -> 86 | I38: =IF(H38>=80,"H1",IF(H38>=75,"H2A",IF(H38>=70,"H2B",IF(H38>=65,"H3",IF(H38>=50,"P","N"))))) -> H1 | J38: ='Homework 1'!C38 -> 5 | K38: ='Homework 2'!C38 -> 5 | L38: ='Homework 3'!C38 -> 4.75 | M38: ='Homework 4'!C38 -> 5 | N38: ='Assignment 1'!C38 -> 16 | O38: ='Assignment 2'!C38 -> 14.75 | P38: ='Assignment 3'!C38 -> 18 | Q38: =Presentation!C38 -> 17.5
... A42: ZHU, Qing | B42: 300335 | C42: 1442961 | D42: zhuqz4 | E42: Computational Differential Equations (MAST90026_2024_SM1), Practical 1 (1), and Practical 2 (1) | F42: 1442961 | G42: =J42+K42+L42+M42+N42+O42+P42+Q42 -> 87 | H42: =_xlfn.CEILING.MATH((G42)) -> 87 | I42: =IF(H42>=80,"H1",IF(H42>=75,"H2A",IF(H42>=70,"H2B",IF(H42>=65,"H3",IF(H42>=50,"P","N"))))) -> H1 | J42: ='Homework 1'!C42 -> 2.5 | K42: ='Homework 2'!C42 -> 5 | L42: ='Homework 3'!C42 -> 4.25 | M42: ='Homework 4'!C42 -> 5 | N42: ='Assignment 1'!C42 -> 18 | O42: ='Assignment 2'!C42 -> 19.5 | P42: ='Assignment 3'!C42 -> 17 | Q42: =Presentation!C42 -> 15.75
A43: Student, Test | B43: 358473 | D43: 0601e9d2fa303e1e0afb06cd93aa99cbb6db07f8 | E43: Computational Differential Equations (MAST90026_2024_SM1) | G43: =J43+K43+L43+M43+N43+O43+P43+Q43 -> 0 | I43: =IF(H43>=80,"H1",IF(H43>=75,"H2A",IF(H43>=70,"H2B",IF(H43>=65,"H3",IF(H43>=50,"P","N"))))) -> N | J43: ='Homework 1'!C43 -> 0 | K43: ='Homework 2'!C43 -> 0 | L43: ='Homework 3'!C43 -> 0 | M43: ='Homework 4'!C43 -> 0 | N43: ='Assignment 1'!C43 -> 0 | O43: ='Assignment 2'!C43 -> 0 | P43: ='Assignment 3'!C43 -> 0 | Q43: =Presentation!C43 -> 0

Sheet Homework 1
A1: ='Master Grades'!A1 -> Student | B1: ='Master Grades'!C1 -> SIS User ID | C1: Total | D1: Late | E1: 1a | F1: 1b | G1: 2a | H1: 2bi | I1: 2bii | J1: 2c | K1: Notes
A2: ='Master Grades'!A2 -> Points Possible | B2: ='Master Grades'!C2 -> 0 | C2: =SUM(D2:J2) -> 5 | D2: 0 | E2: 0.5 | F2: 0.75 | G2: 0.25 | H2: 1.5 | I2: 1.5 | J2: 0.5
A3: ='Master Grades'!A3 -> CAO, Zhi | B3: ='Master Grades'!C3 -> 1370675 | C3: =SUM(D3:J3) -> 4 | E3: 0.5 | F3: 0.5 | G3: 0.25 | H3: 1 | I3: 1.5 | J3: 0.25 | K3: 1b: When using an existing result in a proof need to say what it is. 2bi: Incorrect BC (RHS) in central difference scheme
A4: ='Master Grades'!A4 -> Cash, Lachlan | B4: ='Master Grades'!C4 -> 995802 | C4: =SUM(D4:J4) -> 4.75 | E4: 0.5 | F4: 0.5 | G4: 0.25 | H4: 1.5 | I4: 1.5 | J4: 0.5 | K4: 1b: When using an existing result in a proof need to say what it is.
A5: ='Master Grades'!A5 -> CHEN, Yiru | B5: ='Master Grades'!C5 -> 1417057 | C5: =SUM(D5:J5) -> 5 | E5: 0.5 | F5: 0.75 | G5: 0.25 | H5: 1.5 | I5: 1.5 | J5: 0.5 | K5: Fantastic assignment!
A6: ='Master Grades'!A6 -> Chen, Yuning | B6: ='Master Grades'!C6 -> 1374388 | C6: =SUM(D6:J6) -> 4.5 | E6: 0.5 | F6: 0.5 | G6: 0.25 | H6: 1.25 | I6: 1.5 | J6: 0.5 | K6: 1b. When using an existing result in a proof need to say what it is. 2: code is very dfficult to read, work on commenting. Also outputs are all returned to the command line which makes code difficult to use.
A7: ='Master Grades'!A7 -> CUI, Kaiyue | B7: ='Master Grades'!C7 -> 1373562 | C7: =SUM(D7:J7) -> 5 | E7: 0.5 | F7: 0.75 | G7: 0.25 | H7: 1.5 | I7: 1.5 | J7: 0.5 | K7: Code readability could use a bit of work
A8: ='Master Grades'!A8 -> Douglas, Gabe | B8: ='Master Grades'!C8 -> 1443406 | C8: =SUM(D8:J8) -> 4.75 | E8: 0.5 | F8: 0.5 | G8: 0.25 | H8: 1.5 | I8: 1.5 | J8: 0.5 | K8: When using a standard result need to state what it is. The result you stated is not true for an arbitrary matrix M.
A9: ='Master Grades'!A9 -> Effiezal Aswadi, Afiq | B9: ='Master Grades'!C9 -> 1555968 | C9: =SUM(D9:J9) -> 4.75 | E9: 0.5 | F9: 0.75 | G9: 0.25 | H9: 1.25 | I9: 1.5 | J9: 0.5 | K9: Must label axes of plots so I know what you're plotting. Small note for 2c, u doesn't approach infinity as epsilon approaches 0 however u' does
A10: ='Master Grades'!A10 -> GONG, Lishi | B10: ='Master Grades'!C10 -> 1436599 | C10: =SUM(D10:J10) -> 4.5 | E10: 0.5 | F10: 0.5 | G10: 0.25 | H10: 1.25 | I10: 1.5 | J10: 0.5 | K10: Need more info around condition number and why you are allowed to use this definition. You didn't calculate/approximate the order of accuracy
A11: ='Master Grades'!A11 -> Griffin, Joel | B11: ='Master Grades'!C11 -> 1072476 | C11: =SUM(D11:J11) -> 5 | E11: 0.5 | F11: 0.75 | G11: 0.25 | H11: 1.5 | I11: 1.5 | J11: 0.5 | K11: Fantastic assignment!
A12: ='Master Grades'!A12 -> HUANG, Yiran | B12: ='Master Grades'!C12 -> 1316006 | C12: =SUM(D12:J12) -> 4.5 | E12: 0.5 | F12: 0.5 | G12: 0.25 | H12: 1.5 | I12: 1.5 | J12: 0.25 | K12: How do you get min(lambda^k) = pi^-2? Order of accuracy incorrect.
A13: ='Master Grades'!A13 -> Iqbal, Shadman | B13: ='Master Grades'!C13 -> 650596 | C13: =SUM(D13:J13) -> 1.25 | E13: 0.5 | F13: 0.25 | G13: 0.25 | H13: 0 | I13: 0 | J13: 0.25 | K13: 1b: Need to define everything in your proof. For example, what is rho(A)? Also need to state how you get to the result that the norm is equal to the maximum eigenvalue. 2b: Your code doesn't use finite differences to solve the BVP. You need to formulate a linear system of equations (i.e., a matrix equation) which you then solve.
A14: ='Master Grades'!A14 -> Jayanthy, Danielle | B14: ='Master Grades'!C14 -> 1063490 | C14: =SUM(D14:J14) -> 2.5 | E14: 0.5 | F14: 0.25 | G14: 0.25 | H14: 0.75 | I14: 0.75 | J14: 0 | K14: 1b: proof missing steps and very difficult to read. 2b: plots have no axes labels so I don't know what you're plotting (and you also haven't provided the total requested number of plots). Also, the language you are use throughout your assignment is inappropriate. You are submitting a piece of assessment at Masters level at university and you are expected to conduct yourself in a professional manner.
... A22: ='Master Grades'!A22 -> Ouyang, Yorking | B22: ='Master Grades'!C22 -> 1051214 | C22: =SUM(D22:J22) -> 5 | E22: 0.5 | F22: 0.75 | G22: 0.25 | H22: 1.5 | I22: 1.5 | J22: 0.5 | K22: Fantastic assignment!
A23: ='Master Grades'!A23 -> Rammohan, Radhik | B23: ='Master Grades'!C23 -> ex.rrammohan | C23: =SUM(D23:J23) -> 0
A24: ='Master Grades'!A24 -> Sheng, Kwan | B24: ='Master Grades'!C24 -> ex.shengk | C24: =SUM(D24:J24) -> 0
A25: ='Master Grades'!A25 -> Smith, Zac | B25: ='Master Grades'!C25 -> 1549443 | C25: =SUM(D25:J25) -> 4.5 | E25: 0.25 | F25: 0.75 | G25: 0.25 | H25: 1.5 | I25: 1.5 | J25: 0.25 | K25: 1a: Taylor expansion is not accurate for large k. 2b: Need to plot axis labels. 2c: conclusion not backed up by your results. Most of the time CFD outperforms CUFD
A26: ='Master Grades'!A26 -> SUN, Guangyue | B26: ='Master Grades'!C26 -> 1510033 | C26: =SUM(D26:J26) -> 3.25 | E26: 0.25 | F26: 0.25 | G26: 0.25 | H26: 1.25 | I26: 1 | J26: 0.25 | K26: 1: Look at solutions to gauge the level of working I expect from derivations and proofs. 2: Order of accuracy notation used incorrectly. Need to justify your decision in 2c. I also can't run your code because of invalid file names. Don't use brackets in file names. Supress output to the command window using ; otherwise code is slow and difficult to use
A27: ='Master Grades'!A27 -> Sutherland, William | B27: ='Master Grades'!C27 -> 1168383 | C27: =SUM(D27:J27) -> 2.75 | D27: -1 | E27: 0.5 | F27: 0.5 | G27: 0.25 | H27: 1 | I27: 1 | J27: 0.5 | K27: 20% late penalty applied. 1b: Notation error using matrix norm. Also when using existing results make sure you state what they are. 2b: Looks like your code is nearly correct but requires some more debugging.
A28: ='Master Grades'!A28 -> Syed Muhammad Naquib Al Aidrus, Nadia | B28: ='Master Grades'!C28 -> 1436936 | C28: =SUM(D28:J28) -> 4.5 | E28: 0.5 | F28: 0.5 | G28: 0.25 | H28: 1.5 | I28: 1.5 | J28: 0.25 | K28: 1b. When using an existing result in a proof need to say what it is. Check errors for both schemes. You'll find central differencing is more accurate for all except eps = 0.0005
A29: ='Master Grades'!A29 -> Tian, Lutong | B29: ='Master Grades'!C29 -> 1322753 | C29: =SUM(D29:J29) -> 3.75 | E29: 0.5 | F29: 0.5 | G29: 0.25 | H29: 1 | I29: 1 | J29: 0.5 | K29: 1b: Some errors in your proof. 2b: Some errors in your numerical scheme. Code looks to be nearly there but requires a bit more debugging to get out correct solution
A30: ='Master Grades'!A30 -> Todd, Matthew | B30: ='Master Grades'!C30 -> 1474916 | C30: =SUM(D30:J30) -> 4.5 | E30: 0.5 | F30: 0.75 | G30: 0.25 | H30: 1.25 | I30: 1.25 | J30: 0.5 | K30: 2b: Your code looks to be nearly there. I think it's your implementation of the boundary conditions that's wrong.
A31: ='Master Grades'!A31 -> Wei, Yizhou | B31: ='Master Grades'!C31 -> 1036484 | C31: =SUM(D31:J31) -> 5 | E31: 0.5 | F31: 0.75 | G31: 0.25 | H31: 1.5 | I31: 1.5 | J31: 0.5 | K31: Fantastic assignment!
A32: ='Master Grades'!A32 -> Wu, Yilei | B32: ='Master Grades'!C32 -> 1349379 | C32: =SUM(D32:J32) -> 2.5 | E32: 0.5 | F32: 0.25 | G32: 0.25 | H32: 1 | I32: 0 | J32: 0.5 | K32: 1b: Proof incorrect, also missing assumptions when using the definition of matrix norm. Couldn't run file q2b_2 since it had errors. Q2b.m looks to be nearly correct but just needs a bit more debugging to get the correct answer
A33: ='Master Grades'!A33 -> Xiao, Shutian | B33: ='Master Grades'!C33 -> 1464811 | C33: =SUM(D33:J33) -> 5 | E33: 0.5 | F33: 0.75 | G33: 0.25 | H33: 1.5 | I33: 1.5 | J33: 0.5 | K33: Fantastic assignment!
A34: ='Master Grades'!A34 -> YAN, Kun | B34: ='Master Grades'!C34 -> 1177465 | C34: =SUM(D34:J34) -> 4.75 | E34: 0.5 | F34: 0.5 | G34: 0.25 | H34: 1.5 | I34: 1.5 | J34: 0.5 | K34: 1b: Proof missing some steps. Avoid using symbolic variables in this course. They are slow and our purpose is to create efficient and fast numerical schemes.
A35: ='Master Grades'!A35 -> Young, Carson | B35: ='Master Grades'!C35 -> 1086178 | C35: =SUM(D35:J35) -> 5 | E35: 0.5 | F35: 0.75 | G35: 0.25 | H35: 1.5 | I35: 1.5 | J35: 0.5 | K35: Fantastic assignment!
A36: ='Master Grades'!A36 -> Yuan, Zuoting | B36: ='Master Grades'!C36 -> 1533296 | C36: =SUM(D36:J36) -> 2.5 | E36: 0.5 | F36: 0.25 | G36: 0.25 | H36: 0.5 | I36: 0.5 | J36: 0.5 | K36: 1b: you haven't actually proved the required result. Have a look at solutions for an example of a correct proof. 2b: code doesn't implement finite difference scheme correctly.
A37: ='Master Grades'!A37 -> Zhang, Andrew | B37: ='Master Grades'!C37 -> 979356 | C37: =SUM(D37:J37) -> 5 | E37: 0.5 | F37: 0.75 | G37: 0.25 | H37: 1.5 | I37: 1.5 | J37: 0.5 | K37: Fantastic assignment! In future please submit plots separately (and at a resolution they are visible).
A38: ='Master Grades'!A38 -> ZHANG, Ziang | B38: ='Master Grades'!C38 -> 1494354 | C38: =SUM(D38:J38) -> 5 | E38: 0.5 | F38: 0.75 | G38: 0.25 | H38: 1.5 | I38: 1.5 | J38: 0.5 | K38: Fantastic assignment! For your own security please also submit plots, just in case there is an issue running your code on my computer.
A39: ='Master Grades'!A39 -> Zhao, Hongyu | B39: ='Master Grades'!C39 -> 1437784 | C39: =SUM(D39:J39) -> 5 | E39: 0.5 | F39: 0.75 | G39: 0.25 | H39: 1.5 | I39: 1.5 | J39: 0.5 | K39: Fantastic assignment!
... A42: ='Master Grades'!A42 -> ZHU, Qing | B42: ='Master Grades'!C42 -> 1442961 | C42: =SUM(D42:J42) -> 2.5 | E42: 0.5 | F42: 0.25 | G42: 0.25 | H42: 0.5 | I42: 0.5 | J42: 0.5 | K42: Next time please zip all files together (i.e., don't submit PDF separately but include in zipped file). 1b: Missing steps and assumptions in proof. 2b: Your code doesn't run so I'm unable to assess it. for correctness.

Sheet Homework 2
A1: ='Master Grades'!A1 -> Student | B1: ='Master Grades'!C1 -> SIS User ID | C1: Total | D1: Late | E1: 1i | F1: 1ii | G1: 2a | H1: 2b | I1: 2c | J1: Notes
A2: ='Master Grades'!A2 -> Points Possible | B2: ='Master Grades'!C2 -> 0 | C2: =SUM(D2:I2) -> 5 | D2: 0 | E2: 1 | F2: 1.5 | G2: 1.5 | H2: 0.5 | I2: 0.5
A3: ='Master Grades'!A3 -> CAO, Zhi | B3: ='Master Grades'!C3 -> 1370675 | C3: =SUM(D3:I3) -> 1.75 | E3: 0.5 | F3: 0.5 | G3: 0.5 | H3: 0.25 | I3: 0 | J3: None of your codes produced the correct solution.
A4: ='Master Grades'!A4 -> Cash, Lachlan | B4: ='Master Grades'!C4 -> 995802 | C4: =SUM(D4:I4) -> 5 | E4: 1 | F4: 1.5 | G4: 1.5 | H4: 0.5 | I4: 0.5
A5: ='Master Grades'!A5 -> CHEN, Yiru | B5: ='Master Grades'!C5 -> 1417057 | C5: =SUM(D5:I5) -> 5 | E5: 1 | F5: 1.5 | G5: 1.5 | H5: 0.5 | I5: 0.5
A6: ='Master Grades'!A6 -> Chen, Yuning | B6: ='Master Grades'!C6 -> 1374388 | C6: =SUM(D6:I6) -> 5 | E6: 1 | F6: 1.5 | G6: 1.5 | H6: 0.5 | I6: 0.5
A7: ='Master Grades'!A7 -> CUI, Kaiyue | B7: ='Master Grades'!C7 -> 1373562 | C7: =SUM(D7:I7) -> 5 | E7: 1 | F7: 1.5 | G7: 1.5 | H7: 0.5 | I7: 0.5
A8: ='Master Grades'!A8 -> Douglas, Gabe | B8: ='Master Grades'!C8 -> 1443406 | C8: =SUM(D8:I8) -> 5 | E8: 1 | F8: 1.5 | G8: 1.5 | H8: 0.5 | I8: 0.5
A9: ='Master Grades'!A9 -> Effiezal Aswadi, Afiq | B9: ='Master Grades'!C9 -> 1555968 | C9: =SUM(D9:I9) -> 4.25 | E9: 1 | F9: 0.75 | G9: 1.5 | H9: 0.5 | I9: 0.5 | J9: Q1ii: Your error is scaling as O(h) for the ghost point method even though it should scale as O(h^2). Suspect error in implementing boundary condition.
A10: ='Master Grades'!A10 -> GONG, Lishi | B10: ='Master Grades'!C10 -> 1436599 | C10: =SUM(D10:I10) -> 4.5 | E10: 1 | F10: 1.5 | G10: 1.5 | H10: 0 | I10: 0.5 | J10: Q2b: Error should decay faster than your plot. Given your collocation scheme looks like it's working correctly I think your error calculation might be wrong
A11: ='Master Grades'!A11 -> Griffin, Joel | B11: ='Master Grades'!C11 -> 1072476 | C11: =SUM(D11:I11) -> 5 | E11: 1 | F11: 1.5 | G11: 1.5 | H11: 0.5 | I11: 0.5 | J11: Your solution for the error is correct (and I get exactly the same thing). What you are seeing is round-off error due to not being able to represent the solution to the linear system exactly using floating point arithmetic
A12: ='Master Grades'!A12 -> HUANG, Yiran | B12: ='Master Grades'!C12 -> 1316006 | C12: =SUM(D12:I12) -> 2.75 | E12: 0.5 | F12: 0.5 | G12: 1 | H12: 0.25 | I12: 0.5 | J12: On your second attempt you still didn't submit all the code needed for you programs to run. Unfortunately I cannot give you another submission attempt and will not be changing your grade. Q1ii: Your second order solution appears to only have first order accuracy (although I can't verify this since I don't have your code).
A13: ='Master Grades'!A13 -> Iqbal, Shadman | B13: ='Master Grades'!C13 -> 650596 | C13: =SUM(D13:I13) -> 5 | E13: 1 | F13: 1.5 | G13: 1.5 | H13: 0.5 | I13: 0.5 | J13: Fantastic work!
A14: ='Master Grades'!A14 -> Jayanthy, Danielle | B14: ='Master Grades'!C14 -> 1063490 | C14: =SUM(D14:I14) -> 3.75 | E14: 0.75 | F14: 1 | G14: 1.5 | H14: 0 | I14: 0.5 | J14: Q1: Code for both i and ii doesn't run when number of elements is increased above 92. I suspect there is something strange going on with the s function. Q2b: You are multiplying instead of adding each point in the error calculation. My guess is this is why your error is unrealistically small.
A15: ='Master Grades'!A15 -> Jiang, Zhuochen | B15: ='Master Grades'!C15 -> 1502683 | C15: =SUM(D15:I15) -> 3.5 | E15: 1 | F15: 0.5 | G15: 1.25 | H15: 0.25 | I15: 0.5 | J15: Q1ii: Solution incorrect. Q2a cheb.m not included in submissions. Assignment explicitly states "include all necessary files for your program to run". Q2b: code does not run due to error.
A16: ='Master Grades'!A16 -> Kim, Jiseon | B16: ='Master Grades'!C16 -> 884343 | C16: =SUM(D16:I16) -> 4 | E16: 1 | F16: 0.75 | G16: 1.5 | H16: 0.25 | I16: 0.5 | J16: Q1: Second order method appears to only be giving O(h) convergence. Suspect issue in implementing boundary condition. Q2b: Issue with numerical integration/quadrature. You tried to do 0/0 numerically which gives an error.
A17: ='Master Grades'!A17 -> Li, Juji | B17: ='Master Grades'!C17 -> 1510683 | C17: =SUM(D17:I17) -> 3.25 | E17: 1 | F17: 0.75 | G17: 1 | H17: 0.5 | I17: 0 | J17: Q1: Second order method appears to only be giving O(h) convergence. Suspect issue in implementing boundary condition. Q2: Collocation method not working correctly (issue with implementation of boundary conditions. Q2c: Haven't answered the question that was asked.
A18: ='Master Grades'!A18 -> Li, Zhihan | B18: ='Master Grades'!C18 -> 1074491 | C18: =SUM(D18:I18) -> 2 | E18: 0.5 | F18: 0.5 | G18: 0.5 | H18: 0.25 | I18: 0.25 | J18: Q1: code gives incorrect solution and you haven't discussed anything about how you implemented the scheme so it's difficult for me to give you many marks. Q2a: again code doesn't give correct solution. Q2c: Need to discuss how you adjust computational domain
A19: ='Master Grades'!A19 -> Ma, Jiayue | B19: ='Master Grades'!C19 -> 1495622 | C19: =SUM(D19:I19) -> 1.75 | E19: 0.25 | F19: 0.5 | G19: 1 | H19: 0 | I19: 0 | J19: Q1: Your code doesn't run so I'm unable to assess its correctness. Q2 your code also didn't run, however I was able to give you some marks for this part because it only required a small modification to get it working. In future be very careful that your code can actually execute before submitting.
A20: ='Master Grades'!A20 -> Mccallum, Liam | B20: ='Master Grades'!C20 -> 992893 | C20: =SUM(D20:I20) -> 4.5 | E20: 1 | F20: 1.5 | G20: 1.5 | H20: 0 | I20: 0.5 | J20: Please structure your submission more logically. Only submit files which are needed and put all results (so both written and plots) into a single document. 2b: error not calculated
A21: ='Master Grades'!A21 -> Mifsud, Nathanael | B21: ='Master Grades'!C21 -> 1181978 | C21: =SUM(D21:I21) -> 5 | E21: 1 | F21: 1.5 | G21: 1.5 | H21: 0.5 | I21: 0.5 | J21: Please submit everything (i.e., both PDF and code) into a single zipped file
A22: ='Master Grades'!A22 -> Ouyang, Yorking | B22: ='Master Grades'!C22 -> 1051214 | C22: =SUM(D22:I22) -> 5 | E22: 1 | F22: 1.5 | G22: 1.5 | H22: 0.5 | I22: 0.5
A23: ='Master Grades'!A23 -> Rammohan, Radhik | B23: ='Master Grades'!C23 -> ex.rrammohan | C23: =SUM(D23:I23) -> 0
A24: ='Master Grades'!A24 -> Sheng, Kwan | B24: ='Master Grades'!C24 -> ex.shengk | C24: =SUM(D24:I24) -> 0
A25: ='Master Grades'!A25 -> Smith, Zac | B25: ='Master Grades'!C25 -> 1549443 | C25: =SUM(D25:I25) -> 3.5 | E25: 1 | F25: 1.5 | G25: 0.5 | H25: 0.25 | I25: 0.25 | J25: Please only submit single PDF for all written work and figures. Assignment was difficult to mark as there were so many files without instruction about what they all were. 2a: solution incorrect. 2b: error calculated incorrectly 2c: Need to state change of coordinates is linear
A26: ='Master Grades'!A26 -> SUN, Guangyue | B26: ='Master Grades'!C26 -> 1510033 | C26: =SUM(D26:I26) -> 3.5 | E26: 0.75 | F26: 1.5 | G26: 0.5 | H26: 0.25 | I26: 0.5 | J26: Submitted files did not run because of invalid filenames. Please be careful with future submissions that I can run them without modification. Must use plot labels/titles/etc so I know what I'm looking at. Please also submit all files needed for your code to run (i.e., cheb.m should be included in the submission). 2a: Solution not correct.
A27: ='Master Grades'!A27 -> Sutherland, William | B27: ='Master Grades'!C27 -> 1168383 | C27: =SUM(D27:I27) -> 1.5 | D27: -2 | E27: 1 | F27: 0 | G27: 1.5 | H27: 0.5 | I27: 0.5 | J27: 1ii: No 2nd order scheme. -40% late penalty
A28: ='Master Grades'!A28 -> Syed Muhammad Naquib Al Aidrus, Nadia | B28: ='Master Grades'!C28 -> 1436936 | C28: =SUM(D28:I28) -> 2.75 | E28: 1 | F28: 0.75 | G28: 0.75 | H28: 0.25 | I28: 0 | J28: 1ii: Solution only exhibits O(h). 2a: error should decrease for increasing N. 2b: error not calculated appropraitely since grid is not evenly spaced. 2c: incorrect
A29: ='Master Grades'!A29 -> Tian, Lutong | B29: ='Master Grades'!C29 -> 1322753 | C29: =SUM(D29:I29) -> 4 | E29: 1 | F29: 1 | G29: 1.5 | H29: 0 | I29: 0.5 | J29: 1ii: Error in your attempt at second order method is first order, looks like a mistake in the BC. 2b: Error should decrease as N is increased, suspect error is in your calculation of the norm since your solution looks right
A30: ='Master Grades'!A30 -> Todd, Matthew | B30: ='Master Grades'!C30 -> 1474916 | C30: =SUM(D30:I30) -> 4 | E30: 1 | F30: 0.5 | G30: 1.5 | H30: 0.5 | I30: 0.5 | J30: Your 2nd order scheme only has 1st order accuracy
A31: ='Master Grades'!A31 -> Wei, Yizhou | B31: ='Master Grades'!C31 -> 1036484 | C31: =SUM(D31:I31) -> 5 | E31: 1 | F31: 1.5 | G31: 1.5 | H31: 0.5 | I31: 0.5
A32: ='Master Grades'!A32 -> Wu, Yilei | B32: ='Master Grades'!C32 -> 1349379 | C32: =SUM(D32:I32) -> 5 | E32: 1 | F32: 1.5 | G32: 1.5 | H32: 0.5 | I32: 0.5
A33: ='Master Grades'!A33 -> Xiao, Shutian | B33: ='Master Grades'!C33 -> 1464811 | C33: =SUM(D33:I33) -> 5 | E33: 1 | F33: 1.5 | G33: 1.5 | H33: 0.5 | I33: 0.5
A34: ='Master Grades'!A34 -> YAN, Kun | B34: ='Master Grades'!C34 -> 1177465 | C34: =SUM(D34:I34) -> 5 | E34: 1 | F34: 1.5 | G34: 1.5 | H34: 0.5 | I34: 0.5
A35: ='Master Grades'!A35 -> Young, Carson | B35: ='Master Grades'!C35 -> 1086178 | C35: =SUM(D35:I35) -> 5 | E35: 1 | F35: 1.5 | G35: 1.5 | H35: 0.5 | I35: 0.5
A36: ='Master Grades'!A36 -> Yuan, Zuoting | B36: ='Master Grades'!C36 -> 1533296 | C36: =SUM(D36:I36) -> 1.5 | E36: 0.5 | F36: 0.5 | G36: 0.5 | H36: 0 | I36: 0 | J36: Since your code doesn't work and you didn't submit any handwritten/typed working it's hard for me to give you many grades. Also please submit all files that you need for your code to run in the same folder (so that includes cheb.m). Please also submit plots in a separate document so I don't have to search through your code to try and generate them
A37: ='Master Grades'!A37 -> Zhang, Andrew | B37: ='Master Grades'!C37 -> 979356 | C37: =SUM(D37:I37) -> 5 | E37: 1 | F37: 1.5 | G37: 1.5 | H37: 0.5 | I37: 0.5
A38: ='Master Grades'!A38 -> ZHANG, Ziang | B38: ='Master Grades'!C38 -> 1494354 | C38: =SUM(D38:I38) -> 5 | E38: 1 | F38: 1.5 | G38: 1.5 | H38: 0.5 | I38: 0.5
A39: ='Master Grades'!A39 -> Zhao, Hongyu | B39: ='Master Grades'!C39 -> 1437784 | C39: =SUM(D39:I39) -> 5 | E39: 1 | F39: 1.5 | G39: 1.5 | H39: 0.5 | I39: 0.5
A40: ='Master Grades'!A40 -> ZHAO, Yang | B40: ='Master Grades'!C40 -> 1580719 | C40: =SUM(D40:I40) -> 5 | E40: 1 | F40: 1.5 | G40: 1.5 | H40: 0.5 | I40: 0.5
...

Sheet Homework 3
A1: Student | B1: SIS User ID | C1: Total | D1: Late | E1: Q1 | F1: Q2 | G1: Q3 | H1: Notes
A2: Points Possible | B2: 0 | C2: =SUM(D2:G2) -> 5 | D2: 0 | E2: 1.5 | F2: 1 | G2: 2.5
A3: CAO, Zhi | B3: 1370675 | C3: =SUM(D3:G3) -> 4.25 | D3: 0 | E3: 1 | F3: 0.75 | G3: 2.5 | H3: Q1: Dirichlet BC not encorporated correctly. Only 3 degrees of freedom. Q2: Again Dirichlet conditions not encorporated correctly
A4: Cash, Lachlan | B4: 995802 | C4: =SUM(D4:G4) -> 4.75 | D4: 0 | E4: 1.25 | F4: 1 | G4: 2.5 | H4: Q1: When implementing FEM we move all known quantities to the RHS of the linear system, i.e., should have 3x3 matrix. Q2: switched q to f part way through (I haven't subtracted any marks for this but be careful next time).
A5: CHEN, Yiru | B5: 1417057 | C5: =SUM(D5:G5) -> 4.75 | D5: 0 | E5: 1.5 | F5: 0.75 | G5: 2.5 | H5: Q2: Dirichlet condition not quite implemented correctly
A6: Chen, Yuning | B6: 1374388 | C6: =SUM(D6:G6) -> 4.75 | D6: 0 | E6: 1.5 | F6: 0.75 | G6: 2.5 | H6: Q2: Dirichlet condition not quite implemented correctly
A7: CUI, Kaiyue | B7: 1373562 | C7: =SUM(D7:G7) -> 4.75 | D7: 0 | E7: 1.5 | F7: 0.75 | G7: 2.5 | H7: Q2: Dirichlet condition not quite implemented correctly
A8: Douglas, Gabe | B8: 1443406 | C8: =SUM(D8:G8) -> 5 | D8: 0 | E8: 1.5 | F8: 1 | G8: 2.5
A9: Effiezal Aswadi, Afiq | B9: 1555968 | C9: =SUM(D9:G9) -> 2.5 | D9: 0 | E9: 0 | F9: 0 | G9: 2.5 | H9: Q1: You make reference to a derivation in Q3 but I don't see any derivation in your submission. Q2: You have derived the FEM equations, not the Galerkin equations. FEM is a subset of Galerking methods.
A10: GONG, Lishi | B10: 1436599 | C10: =SUM(D10:G10) -> 3 | D10: 0 | E10: 0 | F10: 0.5 | G10: 2.5 | H10: Q1: You haven't done any derivation. Q2: Dirichlet condition not handled correctly, u not defined.
A11: Griffin, Joel | B11: 1072476 | C11: =SUM(D11:G11) -> 5 | D11: 0 | E11: 1.5 | F11: 1 | G11: 2.5 | H11: Great observation about the loglog plot. This is one of their properties that makes them such a power tool.
A12: HUANG, Yiran | B12: 1316006 | C12: =SUM(D12:G12) -> 4.5 | D12: 0 | E12: 1.5 | F12: 0.5 | G12: 2.5 | H12: Q2: You state you need v(a)=0 which is incorrect, but then you (correctly) include it in your final answer. Dirichlet condition also not handled correctly.
A13: Iqbal, Shadman | B13: 650596 | C13: =SUM(D13:G13) -> 4.25 | D13: 0 | E13: 1 | F13: 0.75 | G13: 2.5 | H13: Q1: You still need to calculate integrals on E1 and E4 because your basis functions defined around x1 and x3 will be non-zero here. Q2: nearly there but you haven't quite considered the Dirichlet condition correctly. See my solution.
A14: Jayanthy, Danielle | B14: 1063490 | C14: =SUM(D14:G14) -> 2.5 | D14: 0 | E14: 0.75 | F14: 0.25 | G14: 1.5 | H14: Q1: You haven't used the information about the grid to define your linear system, everything is left unevaluated. Q2: Neither boundary condition handled correctly, see my solutions. Q3: Unfortunately you didn't quite get there with the code
A15: Jiang, Zhuochen | B15: 1502683 | C15: =SUM(D15:G15) -> 4 | D15: 0 | E15: 0.75 | F15: 0.75 | G15: 2.5 | H15: Q1: phi1 and phi3 not defined correctly. phi1 is non zero on [1/4,1/2] and phi3 nonzero over [1/2,3/4]. Q2: Dirichlet condition not quite handled correctly
A16: Kim, Jiseon | B16: 884343 | C16: =SUM(D16:G16) -> 2.25 | D16: 0 | E16: 1.5 | F16: 0.25 | G16: 0.5 | H16: Q2: You haven't finished deriving the Galerkin equations (the hard work starts when you substitute all the things you've defined into your weak form). Q3: Unforunately your code doesn't solve the problem correctly and you haven't followed the approach demonstrated in class so I'm unable to give you many method marks.
A17: Li, Juji | B17: 1510683 | C17: =SUM(D17:G17) -> 2.75 | D17: 0 | E17: 1 | F17: 0.75 | G17: 1 | H17: Q1: You haven't defined the linear system with the relevant parts removed. Q2: Dirichlet boundary condition not implemented correctly. Q3: You haven't solved for different values of N. I don't know what your plot is because the Max grid norm is a scalar for the whole domain, i.e., independent of x
A18: Li, Zhihan | B18: 1074491 | C18: =SUM(D18:G18) -> 4.75 | D18: 0 | E18: 1.5 | F18: 0.75 | G18: 2.5 | H18: Q2: You actually need to do the bit you stated at the end and move all known quantities to the RHS.
A19: Ma, Jiayue | B19: 1495622 | C19: =SUM(D19:G19) -> 2.25 | D19: 0 | E19: 1.25 | F19: 0 | G19: 1 | H19: Q1: Need to evaluate F. Q2: There's no derivation here, just a couple of equations. Q3: Unfortunately your code doesn't solve the problem correctly and you haven't provided the code that generates your plots.
A20: Mccallum, Liam | B20: 992893 | C20: =SUM(D20:G20) -> 4.75 | D20: 0 | E20: 1.5 | F20: 0.75 | G20: 2.5 | H20: In future please write on one side of the page because it's really hard to read your working with the writing on the other side leaking through (I haven't deducted any marks for this). Q2: You can just define phiN(b) = 1 and everything works out well. Q3: Suppress unnecessary output from being output to the command window as this slows down your code
... A22: Ouyang, Yorking | B22: 1051214 | C22: =SUM(D22:G22) -> 4.75 | D22: 0 | E22: 1.5 | F22: 0.75 | G22: 2.5 | H22: Q1: Just a small note, phi1 and phi5 are NOT in the trial space (as you stated in your first line). I haven't taken a mark off for this though since it's a fairly minor point and the rest of your solution was correct. Q2: Dirichlet condition not quite implemented correctly.
A23: Rammohan, Radhik | B23: ex.rrammohan | C23: =SUM(D23:G23) -> 0 | D23: 0
A24: Sheng, Kwan | B24: ex.shengk | C24: =SUM(D24:G24) -> 0 | D24: 0
A25: Smith, Zac | B25: 1549443 | C25: =SUM(D25:G25) -> 3.5 | D25: 0 | E25: 1.5 | F25: 0.5 | G25: 1.5 | H25: Q2: BC's not handled correctly and since you haven't explained what you’re doing in your derivation it's hard to follow. Q3: Incorrect solution, error should approach zero
A26: SUN, Guangyue | B26: 1510033 | C26: =SUM(D26:G26) -> 1.75 | D26: 0 | E26: 1.5 | F26: 0.25 | G26: 0 | H26: Q2: BC's not handled correctly. Q3: You submitted code that didn't run, I had to modify the file names. There's also no error plot to verify whether your calculated solution is correct. Computed solution also incorrect.
A27: Sutherland, William | B27: 1168383 | C27: =SUM(D27:G27) -> 3.25 | D27: -1 | E27: 1.5 | F27: 0.75 | G27: 2 | H27: Late penalty -1. Q2: Dirichlet BC not quite handled correctly. Q3: Error should scale as h^2 (N^-2) so something has gone wrong in your code but at least you're getting the right solution.
A28: Syed Muhammad Naquib Al Aidrus, Nadia | B28: 1436936 | C28: =SUM(D28:G28) -> 3.25 | D28: 0 | E28: 1.5 | F28: 0.25 | G28: 1.5 | H28: Q2: Neither BC handled correctly. Q3: Unfortunately code doesn't solve problem correctly but looks like you're getting close!
A29: Tian, Lutong | B29: 1322753 | C29: =SUM(D29:G29) -> 4 | D29: 0 | E29: 0.75 | F29: 0.75 | G29: 2.5 | H29: Q1: Since you have Dirichlet BC's should only have a 3x3 system. Q2: Dirichlet BC not handled correctly
A30: Todd, Matthew | B30: 1474916 | C30: =SUM(D30:G30) -> 4.25 | D30: 0 | E30: 1.5 | F30: 0.25 | G30: 2.5 | H30: Q2: You've assembled the finite element system not the Galerkin equations. Finite Element method is a subset of Galerkin methods.
A31: Wei, Yizhou | B31: 1036484 | C31: =SUM(D31:G31) -> 4.75 | D31: 0 | E31: 1.5 | F31: 0.75 | G31: 2.5 | H31: Q1: Your answer is correct and I've given you full marks for it however you've created a lot of extra work for yourself by not working in H^1_0 from the very start. Q2: You actually need to do the final paragraph of your answer, i.e., you haven't finished deriving the Galerkin equations for this problem.
A32: Wu, Yilei | B32: 1349379 | C32: =SUM(D32:G32) -> 2.75 | D32: 0 | E32: 0 | F32: 0.25 | G32: 2.5 | H32: Q1: Question asked you to derive not solve using code. Q2: Variational form incorrect. Wrong sobolev space used. Dirichlet condition handled incorrectly.
A33: Xiao, Shutian | B33: 1464811 | C33: =SUM(D33:G33) -> 4.75 | D33: 0 | E33: 1.5 | F33: 0.75 | G33: 2.5 | H33: Q2: Dirichlet condition not implemented correctly
A34: YAN, Kun | B34: 1177465 | C34: =SUM(D34:G34) -> 4.25 | D34: 0 | E34: 1.5 | F34: 0.25 | G34: 2.5 | H34: Q2: BC's not handled correctly. Given basis not used in test space.
A35: Young, Carson | B35: 1086178 | C35: =SUM(D35:G35) -> 5 | D35: 0 | E35: 1.5 | F35: 1 | G35: 2.5
A36: Yuan, Zuoting | B36: 1533296 | C36: =SUM(D36:G36) -> 1 | D36: 0 | E36: 0 | F36: 0 | G36: 1 | H36: Please submit ALL files (including PDF) in a single zip file. Q1: You haven't shown me how you derived any of these quantities and your formatting doesn't make any sense, and most quantities you haven't defined. Q2: You haven't submitted a derivation (which is what the question asked for). Q3: Your code doesn't solve the problem correctly.
A37: Zhang, Andrew | B37: 979356 | C37: =SUM(D37:G37) -> 5 | D37: 0 | E37: 1.5 | F37: 1 | G37: 2.5
A38: ZHANG, Ziang | B38: 1494354 | C38: =SUM(D38:G38) -> 4.75 | D38: 0 | E38: 1.5 | F38: 0.75 | G38: 2.5 | H38: Q2: Dirichlet condition not implemented correctly
A39: Zhao, Hongyu | B39: 1437784 | C39: =SUM(D39:G39) -> 4.75 | D39: 0 | E39: 1.5 | F39: 0.75 | G39: 2.5 | H39: Q2: Dirichlet condition not implemented correctly. Q3: Just a note for next time, the code you submit to me should produce the plots you submit.
A40: ZHAO, Yang | B40: 1580719 | C40: =SUM(D40:G40) -> 4 | D40: 0 | E40: 1.5 | F40: 0.5 | G40: 2 | H40: Q2: Nearly there but BC's not quite incorporated correctly. Q3: Something unusual is going on with your code because when run for larger N the error doesn't continue to decrease
A41: Zhou, Howie | B41: 1270455 | C41: =SUM(D41:G41) -> 5 | D41: 0 | E41: 1.5 | F41: 1 | G41: 2.5
...

Sheet Homework 4
A1: Student | B1: SIS User ID | C1: Total | D1: Late | E1: Q1 | F1: Q2 | G1: Q3 | H1: Notes
A2: Points Possible | B2: 0 | C2: =SUM(D2:G2) -> 5 | D2: 0 | E2: 2 | F2: 1.5 | G2: 1.5
A3: CAO, Zhi | B3: 1370675 | C3: =SUM(D3:G3) -> 4 | E3: 2 | F3: 0.5 | G3: 1.5 | H3: Q2: Code produces an error
A4: Cash, Lachlan | B4: 995802 | C4: =SUM(D4:G4) -> 4 | D4: -1 | E4: 2 | F4: 1.5 | G4: 1.5 | H4: Late penalty -1.
A5: CHEN, Yiru | B5: 1417057 | C5: =SUM(D5:G5) -> 5 | E5: 2 | F5: 1.5 | G5: 1.5 | H5: Q3: I think you might be a bit confused with which method is which. Newton's method uses finite differences for the derivatives. No need to do a fixed point iteration here
A6: Chen, Yuning | B6: 1374388 | C6: =SUM(D6:G6) -> 3.5 | E6: 2 | F6: 1 | G6: 0.5 | H6: Q2: Function definition in wrong form. Q3: Solution incorrect and no test for convergence
A7: CUI, Kaiyue | B7: 1373562 | C7: =SUM(D7:G7) -> 5 | E7: 2 | F7: 1.5 | G7: 1.5
A8: Douglas, Gabe | B8: 1443406 | C8: =SUM(D8:G8) -> 5 | E8: 2 | F8: 1.5 | G8: 1.5
A9: Effiezal Aswadi, Afiq | B9: 1555968 | C9: =SUM(D9:G9) -> 4 | E9: 2 | F9: 0.5 | G9: 1.5 | H9: Q2: Function gives incorrect output
A10: GONG, Lishi | B10: 1436599 | C10: =SUM(D10:G10) -> 4 | E10: 2 | F10: 0.5 | G10: 1.5 | H10: Q2: Function gives incorrect output
A11: Griffin, Joel | B11: 1072476 | C11: =SUM(D11:G11) -> 5 | E11: 2 | F11: 1.5 | G11: 1.5 | H11: Q3: Be aware that your code is inefficient for large systems. Best to only use anonymous functions for low dimensional functions
A12: HUANG, Yiran | B12: 1316006 | C12: =SUM(D12:G12) -> 4.5 | E12: 2 | F12: 1 | G12: 1.5 | H12: Q2: Function definition in wrong form
A13: Iqbal, Shadman | B13: 650596 | C13: =SUM(D13:G13) -> 4 | E13: 2 | F13: 0.5 | G13: 1.5 | H13: Q2: Function gives incorrect output
A14: Jayanthy, Danielle | B14: 1063490 | C14: =SUM(D14:G14) -> 3.75 | E14: 2 | F14: 1 | G14: 0.75 | H14: Q2: Function/file name definition in wrong form. Q3: Solution incorrect
A15: Jiang, Zhuochen | B15: 1502683 | C15: =SUM(D15:G15) -> 3.5 | E15: 2 | F15: 0 | G15: 1.5 | H15: Q2: No code submitted and even after I copied and pasted the code from your PDF it gives incorrect output
A16: Kim, Jiseon | B16: 884343 | C16: =SUM(D16:G16) -> 4 | E16: 2 | F16: 0.5 | G16: 1.5 | H16: Q2: Function gives incorrect output
A17: Li, Juji | B17: 1510683 | C17: =SUM(D17:G17) -> 4 | E17: 2 | F17: 0.5 | G17: 1.5 | H17: Q2: f is a function not a constant
A18: Li, Zhihan | B18: 1074491 | C18: =SUM(D18:G18) -> 4.25 | E18: 2 | F18: 1.5 | G18: 0.75 | H18: Q3: Code gives error when evaluating. Once I fixed your code it produces the correct solution but plot is missing labels on axes. Your tolerance is also really small and near machine epsilon and so round off errors could very easily get you stuck in an infinite loop
A19: Ma, Jiayue | B19: 1495622 | C19: =SUM(D19:G19) -> 4.5 | E19: 2 | F19: 1 | G19: 1.5 | H19: Q2: Function gives incorrect output (but it's close so have a look and see if you can figure out what's going wrong)
A20: Mccallum, Liam | B20: 992893 | C20: =SUM(D20:G20) -> 4 | E20: 2 | F20: 0.5 | G20: 1.5 | H20: Q2: Function gives incorrect output
A21: Mifsud, Nathanael | B21: 1181978 | C21: =SUM(D21:G21) -> 4.5 | E21: 2 | F21: 1.5 | G21: 1 | H21: Q3: Code gives error when evaluating. Once I fixed your code it runs correctly.
A22: Ouyang, Yorking | B22: 1051214 | C22: =SUM(D22:G22) -> 5 | E22: 2 | F22: 1.5 | G22: 1.5
A23: Rammohan, Radhik | B23: ex.rrammohan | C23: =SUM(D23:G23) -> 0
A24: Sheng, Kwan | B24: ex.shengk | C24: =SUM(D24:G24) -> 0
A25: Smith, Zac | B25: 1549443 | C25: =SUM(D25:G25) -> 3 | E25: 2 | F25: 0.5 | G25: 0.5 | H25: Q2: Fej should contain two values. Q3: Code produces incorrect result and I don't see any part of your code that iterates until solution is converged
A26: SUN, Guangyue | B26: 1510033 | C26: =SUM(D26:G26) -> 0.75 | D26: -1 | E26: 0 | F26: 0.5 | G26: 1.25 | H26: Late penalty -1. Q1: Question asked you to show not do a numerical calculation on a single case. Q2: You didn't submit a function with the required function declaration. Q3: Code produces incorrect result. I think it's just a small error potentially due to some incorrect signs.
A27: Sutherland, William | B27: 1168383 | C27: =SUM(D27:G27) -> 4.5 | E27: 2 | F27: 1.5 | G27: 1 | H27: Q3: Incorrect solution. I think because your definition for F is wrong.
A28: Syed Muhammad Naquib Al Aidrus, Nadia | B28: 1436936 | C28: =SUM(D28:G28) -> 4.25 | E28: 2 | F28: 1.5 | G28: 0.75 | H28: Q3: I'm not sure what your Finite Difference Method plot is since you can't solve a non-linear equation using finite differences alone. Your curve for Newton Method is also incorrect, I think due to an incorrect definition of F
A29: Tian, Lutong | B29: 1322753 | C29: =SUM(D29:G29) -> 4 | E29: 2 | F29: 0.5 | G29: 1.5 | H29: Q2: Function file name in incorrect form (function declaration must correspond to same file name otherwise function can't be called) and also incorrect output
A30: Todd, Matthew | B30: 1474916 | C30: =SUM(D30:G30) -> 4.75 | E30: 2 | F30: 1.25 | G30: 1.5 | H30: Q2: Output in incorrect order
A31: Wei, Yizhou | B31: 1036484 | C31: =SUM(D31:G31) -> 5 | E31: 2 | F31: 1.5 | G31: 1.5
A32: Wu, Yilei | B32: 1349379 | C32: =SUM(D32:G32) -> 5 | E32: 2 | F32: 1.5 | G32: 1.5
A33: Xiao, Shutian | B33: 1464811 | C33: =SUM(D33:G33) -> 5 | E33: 2 | F33: 1.5 | G33: 1.5
A34: YAN, Kun | B34: 1177465 | C34: =SUM(D34:G34) -> 5 | E34: 2 | F34: 1.5 | G34: 1.5
